Workbook

Sheet AMK SETTLEMENT CALC NEW
A3: MONTH/YEAR: | B3: 46023 | E3: MONTH/YEAR: | F3: =B3 | I3: MONTH/YEAR: | J3: =B3 | M3: MONTH/YEAR: | N3: =B3 | Q3: MONTH/YEAR: | R3: =B3 | U3: MONTH/YEAR: | V3: =B3 | Y3: MONTH/YEAR: | Z3: =B3 | AD3: MONTH/YEAR: | AE3: =B3 | AI3: MONTH/YEAR: | AJ3: =AE3
A4: BRANCH: | B4: CASA DENTAL AMK PTE LTD | E4: BRANCH: | F4: CASA DENTAL AMK PTE LTD | I4: BRANCH: | J4: CASA DENTAL AMK PTE LTD | M4: BRANCH: | N4: CASA DENTAL AMK PTE LTD | Q4: BRANCH: | R4: CASA DENTAL AMK PTE LTD | U4: BRANCH: | V4: CASA DENTAL AMK PTE LTD | Y4: BRANCH: | Z4: CASA DENTAL AMK PTE LTD | AD4: BRANCH: | AE4: CASA DENTAL AMK PTE LTD | AI4: BRANCH: | AJ4: CASA DENTAL AMK PTE LTD
A5: ALL PROVIDERS SETTLEMENT | E5: DR CHAN | I5: DR JASMINE | M5: DR JIAWEN | Q5: DR KALIE | U5: DR JOLEEN | Y5: DR BRANDON | AD5: DR JEAN CHONG | AI5: DR ANDREW YIN
C6: ADMIN CHARGES | G6: ADMIN CHARGES | J6: TOTALS | K6: ADMIN CHARGES | O6: ADMIN CHARGES | S6: ADMIN CHARGES | W6: ADMIN CHARGES | AA6: ADMIN CHARGES | AF6: ADMIN CHARGES | AK6: ADMIN CHARGES
A7: AIA | B7: None_test | C7: =B7*0.05*1.09 | E7: AIA | G7: =F7*0.05*1.09 | I7: AIA | K7: =J7*0.05*1.09 | M7: AIA | O7: =N7*0.05*1.09 | Q7: AIA | S7: =R7*0.05*1.09 | U7: AIA | W7: =V7*0.05*1.09 | Y7: AIA | AA7: =Z7*0.05*1.09 | AD7: AIA | AF7: =AE7*0.05*1.09 | AI7: AIA | AK7: =AJ7*0.05*1.09
A8: ALLIANCE | C8: =B8*0.05*1.09 | E8: ALLIANCE | G8: =F8*0.05*1.09 | I8: ALLIANCE | K8: =J8*0.05*1.09 | M8: ALLIANCE | O8: =N8*0.05*1.09 | U8: ALLIANCE | W8: =V8*0.05*1.09 | Y8: ALLIANCE | AA8: =Z8*0.05*1.09 | AD8: ALLIANCE | AF8: =AE8*0.05*1.09
A9: AMEX | C9: =B9*0.0195 | E9: AMEX | G9: =F9*0.0195 | I9: AMEX | K9: =J9*0.0195 | M9: AMEX | O9: =N9*0.0195 | Q9: AMEX | S9: =R9*0.0195 | U9: AMEX | W9: =V9*0.0195 | Y9: AMEX | AA9: =Z9*0.0195 | AD9: AMEX | AF9: =AE9*0.0195 | AI9: AMEX | AK9: =AJ9*0.0195
A10: BABYBONUS | C10: =B10*0.008 | E10: BABYBONUS | G10: =F10*0.008 | I10: BABYBONUS | K10: =J10*0.008 | M10: BABYBONUS | O10: =N10*0.008 | U10: BABYBONUS | W10: =V10*0.008 | Y10: BABYBONUS | AA10: =Z10*0.008 | AD10: BABYBONUS | AF10: =AE10*0.008
A11: CASH | E11: CASH | I11: CASH | M11: CASH | Q11: ALLIANCE | S11: =R11*0.05*1.09 | U11: CASH | Y11: CASH | AD11: CASH | AI11: ALLIANCE | AK11: =AJ11*0.05*1.09
A12: CASA VOUCHER | E12: CASA VOUCHER | I12: CASA VOUCHER | M12: CASA VOUCHER | Q12: CASH | U12: CASA VOUCHER | Y12: CASA VOUCHER | AD12: CASA VOUCHER | AI12: CASH
A13: CDC VOUCHER | E13: CDC VOUCHER | I13: CDC VOUCHER | M13: CDC VOUCHER | Q13: CASA VOUCHER | U13: CDC VOUCHER | Y13: CDC VOUCHER | AD13: CDC VOUCHER | AI13: CASA VOUCHER
A14: CHAS | E14: CHAS | I14: CHAS | M14: CHAS | U14: CHAS | Y14: CHAS | AD14: CHAS
A15: CYNERGY | E15: CYNERGY | I15: CYNERGY | M15: CYNERGY | U15: CYNERGY | Y15: CYNERGY | AD15: CYNERGY
A16: DA ADEPT HEALTH | C16: =B16*8% | E16: DA ADEPT HEALTH | G16: =F16*8% | I16: DA ADEPT HEALTH | K16: =J16*8% | M16: DA ADEPT HEALTH | O16: =N16*8% | U16: DA ADEPT HEALTH | W16: =V16*8% | Y16: DA ADEPT HEALTH | AA16: =Z16*8% | AD16: DA ADEPT HEALTH | AF16: =AE16*8%
A17: DEPOSIT | C17: =G17+K17+O17+O17+S17+W17+AA17+AF17 | E17: DEPOSIT | I17: DEPOSIT | M17: DEPOSIT | Q17: DEPOSIT | S17: 0 | U17: DEPOSIT | Y17: DEPOSIT | AD17: DEPOSIT | AI17: DEPOSIT
A18: IHP | C18: =B18*0.051*1.09 | E18: IHP | G18: =F18*0.051*1.09 | I18: IHP | K18: =J18*0.051*1.09 | M18: IHP | O18: =N18*0.051*1.09 | U18: IHP | W18: =V18*0.051*1.09 | Y18: IHP | AA18: =Z18*0.051*1.09 | AD18: IHP | AF18: =AE18*0.051*1.09
A19: JCB | C19: =B19*0.15*1.09 | E19: JCB | G19: =F19*0.15*1.09 | I19: JCB | K19: =J19*0.15*1.09 | M19: JCB | O19: =N19*0.15*1.09 | U19: JCB | W19: =V19*0.15*1.09 | Y19: JCB | AA19: =Z19*0.15*1.09 | AD19: JCB | AF19: =AE19*0.15*1.09
A20: MASTER | C20: =B20*0.021 | E20: MASTER | G20: =F20*0.021 | I20: MASTER | K20: =J20*0.021 | M20: MASTER | O20: =N20*0.021 | U20: MASTER | W20: =V20*0.021 | Y20: MASTER | AA20: =Z20*0.021 | AD20: MASTER | AF20: =AE20*0.021
A21: MEDISAVE | E21: MEDISAVE | I21: MEDISAVE | M21: MEDISAVE | U21: MEDISAVE | Y21: MEDISAVE | AD21: MEDISAVE
A22: mednefits | C22: =B22*20% | E22: mednefits | G22: =F22*20% | I22: mednefits | K22: =J22*20% | M22: mednefits | O22: =N22*20% | U22: mednefits | W22: =V22*20% | Y22: mednefits | AA22: =Z22*20% | AD22: mednefits | AF22: =AE22*20%
A23: MHC | C23: =B23*0.15*1.09 | E23: MHC | G23: =F23*0.15*1.09 | I23: MHC | K23: =J23*0.15*1.09 | M23: MHC | O23: =N23*0.15*1.09 | U23: MHC | W23: =V23*0.15*1.09 | Y23: MHC | AA23: =Z23*0.15*1.09 | AD23: MHC | AF23: =AE23*0.15*1.09
A24: NETS | C24: =B24*0.008 | E24: NETS | G24: =F24*0.008 | I24: NETS | K24: =J24*0.008 | M24: NETS | O24: =N24*0.008 | U24: NETS | W24: =V24*0.008 | Y24: NETS | AA24: =Z24*0.008 | AD24: NETS | AF24: =AE24*0.008
A25: PARKWAY | E25: PARKWAY | G25: =F25*10% | I25: PARKWAY | K25: =J25*10% | M25: PARKWAY | O25: =N25*10% | U25: PARKWAY | W25: =V25*10% | Y25: PARKWAY | AA25: =Z25*10% | AD25: PARKWAY | AF25: =AE25*10%
A26: PAYNOW | E26: PAYNOW | I26: PAYNOW | M26: PAYNOW | U26: PAYNOW | Y26: PAYNOW | AD26: PAYNOW
A27: RHI | E27: RHI | I27: RHI | M27: RHI | U27: RHI | Y27: RHI | AD27: RHI
A28: SAH | C28: =B28*8% | E28: SAH | G28: =F28*8% | I28: SAH | K28: =J28*8% | M28: SAH | O28: =N28*8% | U28: SAH | W28: =V28*8% | Y28: SAH | AA28: =Z28*8% | AD28: SAH | AF28: =AE28*8%
A29: UNION PAY | C29: =B29*2.5% | E29: UNION PAY | G29: =F29*2.5% | I29: UNION PAY | K29: =J29*2.5% | M29: UNION PAY | O29: =N29*2.5% | U29: UNION PAY | W29: =V29*2.5% | Y29: UNION PAY | AA29: =Z29*2.5% | AD29: UNION PAY | AF29: =AE29*2.5%
A30: VISA | C30: =B30*0.021 | E30: VISA | G30: =F30*0.021 | I30: VISA | K30: =J30*0.021 | M30: VISA | O30: =N30*0.021 | U30: VISA | W30: =V30*0.021 | Y30: VISA | AA30: =Z30*0.021 | AD30: VISA | AF30: =AE30*0.021
A31: TOTAL INCOME | B31: =SUM(B7:B30) | C31: =SUM(C7:C30) | E31: DR TOTAL INCOME | F31: =SUM(F7:F30) | G31: =SUM(G7:G30) | I31: DR TOTAL INCOME | J31: =SUM(J7:J30) | K31: =SUM(K7:K30) | M31: DR TOTAL INCOME | N31: =SUM(N7:N30) | O31: =SUM(O7:O30) | U31: DR TOTAL INCOME | V31: =SUM(V7:V30) | W31: =SUM(W7:W30) | Y31: DR TOTAL INCOME | Z31: =SUM(Z7:Z30) | AA31: =SUM(AA7:AA30) | AD31: DR TOTAL INCOME | AE31: =SUM(AE7:AE30) | AF31: =SUM(AF7:AF30)
B33: EXPENSES | F33: DEDUCTIONS | H33: REMARKS | J33: DEDUCTIONS | L33: REMARKS | N33: DEDUCTIONS | P33: REMARKS | R33: DEDUCTIONS | T33: REMARKS | V33: DEDUCTIONS | X33: REMARKS | Z33: DEDUCTIONS | AB33: REMARKS | AE33: DEDUCTIONS | AG33: REMARKS | AJ33: DEDUCTIONS | AL33: REMARKS
B34: ADMIN FEE | C34: =SUM(C7:C30) | F34: ADMIN CHARGES | G34: =G31 | J34: ADMIN CHARGES | K34: =K31 | N34: ADMIN CHARGES | O34: =O31 | R34: ADMIN CHARGES | S34: =#REF! | V34: ADMIN CHARGES | W34: =W31 | Z34: ADMIN CHARGES | AA34: =AA31 | AE34: ADMIN CHARGES | AF34: =AF31 | AJ34: ADMIN CHARGES | AK34: =#REF!
B35: GST | C35: =G35+K35+O35+S35+W35+AA35+AF35+AK35 | F35: GST | J35: GST | N35: GST | R35: GST | V35: GST | Z35: GST | AE35: GST | AJ35: GST
B36: RENTAL | F36: ICC-5 | J36: ICC-5 | N36: ICC-5 | V36: ICC-5 | Z36: ICC-5 | AE36: ICC-5
B37: LOAN INTEREST | F37: PRODUCTS | J37: PRODUCTS | N37: PRODUCTS | V37: PRODUCTS | Z37: PRODUCTS | AE37: PRODUCTS
B38: NEW CATEGORY | C38: Amount
B39: IRAS TAX | F39: ORTHO (B+B) | J39: ORTHO (B+B) | N39: ORTHO (B+B) | V39: ORTHO (B+B) | Z39: ORTHO (B+B) | AE39: ORTHO (B+B)
B40: CK SECRETARIAL / ACCOUNTS SERVICES | F40: ABUTMENTS | J40: ABUTMENTS | N40: ABUTMENTS | V40: ABUTMENTS | Z40: ABUTMENTS | AE40: ABUTMENTS
B41: TOWN COUNCIL | C41: =160.5+103.75 | F41: IMPLANT | J41: IMPLANT | N41: IMPLANT | V41: IMPLANT | Z41: IMPLANT | AE41: IMPLANT
B42: SERVICE & CONSERVANCY CHARGES | C42: 400 | F42: SKY LAB | J42: SKY LAB | N42: SKY LAB | V42: SKY LAB | Z42: SKY LAB | AE42: SKY LAB
B43: SP | F43: DIGICADCAM | J43: DIGICADCAM | N43: DIGICADCAM | V43: DIGICADCAM | Z43: DIGICADCAM | AE43: DIGICADCAM
...

Sheet CLEMENTI SETTLEMENT CALC NEW
A3: MONTH/YEAR: | B3: 46023 | E3: MONTH/YEAR: | F3: =B3 | I3: MONTH/YEAR: | J3: =B3 | M3: MONTH/YEAR: | N3: =B3 | Q3: MONTH/YEAR: | R3: =B3 | U3: MONTH/YEAR: | V3: =B3 | Y3: MONTH/YEAR: | Z3: =B3 | AD3: MONTH/YEAR: | AE3: =B3 | AI3: MONTH/YEAR: | AJ3: =AE3 | AN3: MONTH/YEAR: | AO3: =AE3 | AS3: MONTH/YEAR: | AT3: =AO3 | AX3: MONTH/YEAR: | AY3: =V3
A4: BRANCH: | B4: CASA DENTAL CLEMENTI PTE LTD | E4: BRANCH: | F4: =B4 | I4: BRANCH: | J4: =B4 | M4: BRANCH: | N4: =B4 | Q4: BRANCH: | R4: CASA DENTAL AMK PTE LTD | U4: BRANCH: | V4: =B4 | Y4: BRANCH: | Z4: =B4 | AD4: BRANCH: | AE4: =B4 | AI4: BRANCH: | AJ4: CASA DENTAL AMK PTE LTD | AN4: BRANCH: | AO4: =AE4 | AS4: BRANCH: | AT4: =AO4 | AX4: BRANCH: | AY4: =V4
A5: ALL PROVIDERS SETTLEMENT | E5: DR CHAN KC | I5: DR JASMINE LEE | M5: DR ROCKY LEUNG | Q5: DR KALIE | U5: DR PETER KEITH | Y5: DR HUANG JIAWEN | AD5: DR ANG LI EN | AI5: DR ANDREW YIN | AN5: DR KAREN LEONG | AS5: DR JOLEEN NGOI | AX5: DR CHARLENE YAP
C6: ADMIN CHARGES | G6: ADMIN CHARGES | J6: TOTALS | K6: ADMIN CHARGES | O6: ADMIN CHARGES | S6: ADMIN CHARGES | W6: ADMIN CHARGES | AA6: ADMIN CHARGES | AF6: ADMIN CHARGES | AK6: ADMIN CHARGES | AP6: ADMIN CHARGES | AU6: ADMIN CHARGES | AZ6: ADMIN CHARGES
A7: AIA | C7: =B7*0.05*1.09 | E7: AIA | G7: =F7*0.05*1.09 | I7: AIA | K7: =J7*0.05*1.09 | M7: AIA | O7: =N7*0.05*1.09 | Q7: AIA | S7: =R7*0.05*1.09 | U7: AIA | W7: =V7*0.05*1.09 | Y7: AIA | AA7: =Z7*0.05*1.09 | AD7: AIA | AF7: =AE7*0.05*1.09 | AI7: AIA | AK7: =AJ7*0.05*1.09 | AN7: AIA | AP7: =AO7*0.05*1.09 | AS7: AIA | AU7: =AT7*0.05*1.09 | AX7: AIA | AZ7: =AY7*0.05*1.09
A8: ALLIANCE | C8: =B8*0.05*1.09 | E8: ALLIANCE | G8: =F8*0.05*1.09 | I8: ALLIANCE | K8: =J8*0.05*1.09 | M8: ALLIANCE | O8: =N8*0.05*1.09 | U8: ALLIANCE | W8: =V8*0.05*1.09 | Y8: ALLIANCE | AA8: =Z8*0.05*1.09 | AD8: ALLIANCE | AF8: =AE8*0.05*1.09 | AN8: ALLIANCE | AP8: =AO8*0.05*1.09 | AS8: ALLIANCE | AU8: =AT8*0.05*1.09 | AX8: ALLIANCE | AZ8: =AY8*0.05*1.09
A9: AMEX | C9: =B9*0.0195 | E9: AMEX | G9: =F9*0.0195 | I9: AMEX | K9: =J9*0.0195 | M9: AMEX | O9: =N9*0.0195 | Q9: AMEX | S9: =R9*0.0195 | U9: AMEX | W9: =V9*0.0195 | Y9: AMEX | AA9: =Z9*0.0195 | AD9: AMEX | AF9: =AE9*0.0195 | AI9: AMEX | AK9: =AJ9*0.0195 | AN9: AMEX | AP9: =AO9*0.0195 | AS9: AMEX | AU9: =AT9*0.0195 | AX9: AMEX | AZ9: =AY9*0.0195
A10: BABYBONUS | C10: =B10*0.008 | E10: BABYBONUS | G10: =F10*0.008 | I10: BABYBONUS | K10: =J10*0.008 | M10: BABYBONUS | O10: =N10*0.008 | U10: BABYBONUS | W10: =V10*0.008 | Y10: BABYBONUS | AA10: =Z10*0.008 | AD10: BABYBONUS | AF10: =AE10*0.008 | AN10: BABYBONUS | AP10: =AO10*0.008 | AS10: BABYBONUS | AU10: =AT10*0.008 | AX10: BABYBONUS | AZ10: =AY10*0.008
A11: CASH | E11: CASH | I11: CASH | M11: CASH | Q11: ALLIANCE | S11: =R11*0.05*1.09 | U11: CASH | Y11: CASH | AD11: CASH | AI11: ALLIANCE | AK11: =AJ11*0.05*1.09 | AN11: CASH | AS11: CASH | AX11: CASH
A12: CASA VOUCHER | E12: CASA VOUCHER | I12: CASA VOUCHER | M12: CASA VOUCHER | Q12: CASH | U12: CASA VOUCHER | Y12: CASA VOUCHER | AD12: CASA VOUCHER | AI12: CASH | AN12: CASA VOUCHER | AS12: CASA VOUCHER | AX12: CASA VOUCHER
A13: CDC VOUCHER | E13: CDC VOUCHER | I13: CDC VOUCHER | M13: CDC VOUCHER | Q13: CASA VOUCHER | U13: CDC VOUCHER | Y13: CDC VOUCHER | AD13: CDC VOUCHER | AI13: CASA VOUCHER | AN13: CDC VOUCHER | AS13: CDC VOUCHER | AX13: CDC VOUCHER
A14: CHAS | E14: CHAS | I14: CHAS | M14: CHAS | U14: CHAS | Y14: CHAS | AD14: CHAS | AN14: CHAS | AS14: CHAS | AX14: CHAS
A15: CYNERGY | E15: CYNERGY | I15: CYNERGY | M15: CYNERGY | U15: CYNERGY | Y15: CYNERGY | AD15: CYNERGY | AN15: CYNERGY | AS15: CYNERGY | AX15: CYNERGY
A16: DA ADEPT HEALTH | C16: =B16*8% | E16: DA ADEPT HEALTH | G16: =F16*8% | I16: DA ADEPT HEALTH | K16: =J16*8% | M16: DA ADEPT HEALTH | O16: =N16*8% | U16: DA ADEPT HEALTH | W16: =V16*8% | Y16: DA ADEPT HEALTH | AA16: =Z16*8% | AD16: DA ADEPT HEALTH | AF16: =AE16*8% | AN16: DA ADEPT HEALTH | AP16: =AO16*8% | AS16: DA ADEPT HEALTH | AU16: =AT16*8% | AX16: DA ADEPT HEALTH | AZ16: =AY16*8%
A17: DEPOSIT | C17: =G17+K17+O17+O17+S17+W17+AA17+AF17+AP17+AU17+AZ17 | E17: DEPOSIT | I17: DEPOSIT | M17: DEPOSIT | Q17: DEPOSIT | S17: 0 | U17: DEPOSIT | Y17: DEPOSIT | AD17: DEPOSIT | AI17: DEPOSIT | AN17: DEPOSIT | AS17: DEPOSIT | AX17: DEPOSIT
A18: IHP | C18: =B18*0.051*1.09 | E18: IHP | G18: =F18*0.051*1.09 | I18: IHP | K18: =J18*0.051*1.09 | M18: IHP | O18: =N18*0.051*1.09 | U18: IHP | W18: =V18*0.051*1.09 | Y18: IHP | AA18: =Z18*0.051*1.09 | AD18: IHP | AF18: =AE18*0.051*1.09 | AN18: IHP | AP18: =AO18*0.051*1.09 | AS18: IHP | AU18: =AT18*0.051*1.09 | AX18: IHP | AZ18: =AY18*0.051*1.09
A19: JCB | C19: =B19*0.15*1.09 | E19: JCB | G19: =F19*0.15*1.09 | I19: JCB | K19: =J19*0.15*1.09 | M19: JCB | O19: =N19*0.15*1.09 | U19: JCB | W19: =V19*0.15*1.09 | Y19: JCB | AA19: =Z19*0.15*1.09 | AD19: JCB | AF19: =AE19*0.15*1.09 | AN19: JCB | AP19: =AO19*0.15*1.09 | AS19: JCB | AU19: =AT19*0.15*1.09 | AX19: JCB | AZ19: =AY19*0.15*1.09
A20: MASTER | C20: =B20*0.021 | E20: MASTER | G20: =F20*0.021 | I20: MASTER | K20: =J20*0.021 | M20: MASTER | O20: =N20*0.021 | U20: MASTER | W20: =V20*0.021 | Y20: MASTER | AA20: =Z20*0.021 | AD20: MASTER | AF20: =AE20*0.021 | AN20: MASTER | AP20: =AO20*0.021 | AS20: MASTER | AU20: =AT20*0.021 | AX20: MASTER | AZ20: =AY20*0.021
A21: MEDISAVE | E21: MEDISAVE | I21: MEDISAVE | M21: MEDISAVE | U21: MEDISAVE | Y21: MEDISAVE | AD21: MEDISAVE | AN21: MEDISAVE | AS21: MEDISAVE | AX21: MEDISAVE
A22: mednefits | C22: =B22*20% | E22: mednefits | G22: =F22*20% | I22: mednefits | K22: =J22*20% | M22: mednefits | O22: =N22*20% | U22: mednefits | W22: =V22*20% | Y22: mednefits | AA22: =Z22*20% | AD22: mednefits | AF22: =AE22*20% | AN22: mednefits | AP22: =AO22*20% | AS22: mednefits | AU22: =AT22*20% | AX22: mednefits | AZ22: =AY22*20%
A23: MHC | C23: =B23*0.15*1.09 | E23: MHC | G23: =F23*0.15*1.09 | I23: MHC | K23: =J23*0.15*1.09 | M23: MHC | O23: =N23*0.15*1.09 | U23: MHC | W23: =V23*0.15*1.09 | Y23: MHC | AA23: =Z23*0.15*1.09 | AD23: MHC | AF23: =AE23*0.15*1.09 | AN23: MHC | AP23: =AO23*0.15*1.09 | AS23: MHC | AU23: =AT23*0.15*1.09 | AX23: MHC | AZ23: =AY23*0.15*1.09
A24: NETS | C24: =B24*0.008 | E24: NETS | G24: =F24*0.008 | I24: NETS | K24: =J24*0.008 | M24: NETS | O24: =N24*0.008 | U24: NETS | W24: =V24*0.008 | Y24: NETS | AA24: =Z24*0.008 | AD24: NETS | AF24: =AE24*0.008 | AN24: NETS | AP24: =AO24*0.008 | AS24: NETS | AU24: =AT24*0.008 | AX24: NETS | AZ24: =AY24*0.008
A25: PARKWAY | C25: =B25*10% | E25: PARKWAY | G25: =F25*10% | I25: PARKWAY | K25: =J25*10% | M25: PARKWAY | O25: =N25*10% | U25: PARKWAY | W25: =V25*10% | Y25: PARKWAY | AA25: =Z25*10% | AD25: PARKWAY | AF25: =AE25*10% | AN25: PARKWAY | AP25: =AO25*10% | AS25: PARKWAY | AU25: =AT25*10% | AX25: PARKWAY | AZ25: =AY25*10%
A26: PAYNOW | E26: PAYNOW | I26: PAYNOW | M26: PAYNOW | U26: PAYNOW | Y26: PAYNOW | AD26: PAYNOW | AN26: PAYNOW | AS26: PAYNOW | AX26: PAYNOW
A27: RHI | E27: RHI | I27: RHI | M27: RHI | U27: RHI | Y27: RHI | AD27: RHI | AN27: RHI | AS27: RHI | AX27: RHI
A28: SAH | C28: =B28*8% | E28: SAH | G28: =F28*8% | I28: SAH | K28: =J28*8% | M28: SAH | O28: =N28*8% | U28: SAH | W28: =V28*8% | Y28: SAH | AA28: =Z28*8% | AD28: SAH | AF28: =AE28*8% | AN28: SAH | AP28: =AO28*8% | AS28: SAH | AU28: =AT28*8% | AX28: SAH | AZ28: =AY28*8%
A29: UNION PAY | C29: =B29*2.5% | E29: UNION PAY | G29: =F29*2.5% | I29: UNION PAY | K29: =J29*2.5% | M29: UNION PAY | O29: =N29*2.5% | U29: UNION PAY | W29: =V29*2.5% | Y29: UNION PAY | AA29: =Z29*2.5% | AD29: UNION PAY | AF29: =AE29*2.5% | AN29: UNION PAY | AP29: =AO29*2.5% | AS29: UNION PAY | AU29: =AT29*2.5% | AX29: UNION PAY | AZ29: =AY29*2.5%
A30: VISA | C30: =B30*0.021 | E30: VISA | G30: =F30*0.021 | I30: VISA | K30: =J30*0.021 | M30: VISA | O30: =N30*0.021 | U30: VISA | W30: =V30*0.021 | Y30: VISA | AA30: =Z30*0.021 | AD30: VISA | AF30: =AE30*0.021 | AN30: VISA | AP30: =AO30*0.021 | AS30: VISA | AU30: =AT30*0.021 | AX30: VISA | AZ30: =AY30*0.021
A31: TOTAL INCOME | B31: =SUM(B7:B30) | C31: =SUM(C7:C30) | E31: DR TOTAL INCOME | F31: =SUM(F7:F30) | G31: =SUM(G7:G30) | I31: DR TOTAL INCOME | J31: =SUM(J7:J30) | K31: =SUM(K7:K30) | M31: DR TOTAL INCOME | N31: =SUM(N7:N30) | O31: =SUM(O7:O30) | U31: DR TOTAL INCOME | V31: =SUM(V7:V30) | W31: =SUM(W7:W30) | Y31: DR TOTAL INCOME | Z31: =SUM(Z7:Z30) | AA31: =SUM(AA7:AA30) | AD31: DR TOTAL INCOME | AE31: =SUM(AE7:AE30) | AF31: =SUM(AF7:AF30) | AN31: DR TOTAL INCOME | AO31: =SUM(AO7:AO30) | AP31: =SUM(AP7:AP30) | AS31: DR TOTAL INCOME | AT31: =SUM(AT7:AT30) | AU31: =SUM(AU7:AU30) | AX31: DR TOTAL INCOME | AY31: =SUM(AY7:AY30) | AZ31: =SUM(AZ7:AZ30)
B33: EXPENSES | F33: DEDUCTIONS | H33: REMARKS | J33: DEDUCTIONS | L33: REMARKS | N33: DEDUCTIONS | P33: REMARKS | R33: DEDUCTIONS | T33: REMARKS | V33: DEDUCTIONS | X33: REMARKS | Z33: DEDUCTIONS | AB33: REMARKS | AE33: DEDUCTIONS | AG33: REMARKS | AJ33: DEDUCTIONS | AL33: REMARKS | AO33: DEDUCTIONS | AQ33: REMARKS | AT33: DEDUCTIONS | AV33: REMARKS | AY33: DEDUCTIONS | BA33: REMARKS
B34: ADMIN FEE | C34: =SUM(C7:C30) | F34: ADMIN CHARGES | G34: =G31 | J34: ADMIN CHARGES | K34: =K31 | N34: ADMIN CHARGES | O34: =O31 | R34: ADMIN CHARGES | S34: =#REF! | V34: ADMIN CHARGES | W34: =W31 | Z34: ADMIN CHARGES | AA34: =AA31 | AE34: ADMIN CHARGES | AF34: =AF31 | AJ34: ADMIN CHARGES | AK34: =#REF! | AO34: ADMIN CHARGES | AP34: =AP31 | AT34: ADMIN CHARGES | AU34: =AU31 | AY34: ADMIN CHARGES | AZ34: =AZ31
B35: GST | C35: =K35+O35+AA35+AF35+AM35+AP35+T35+W35+AU35+AZ35 | F35: GST | J35: GST | N35: GST | R35: GST | V35: GST | Z35: GST | AE35: GST | AJ35: GST | AO35: GST | AT35: GST | AY35: GST
B36: RENTAL | F36: ICC-5 | J36: ICC-5 | N36: ICC-5 | V36: ICC-5 | Z36: ICC-5 | AE36: ICC-5 | AO36: ICC-5 | AT36: ICC-5 | AY36: ICC-5
B37: LOAN INTEREST | F37: PRODUCTS | J37: PRODUCTS | N37: PRODUCTS | V37: PRODUCTS | Z37: PRODUCTS | AE37: PRODUCTS | AO37: PRODUCTS | AT37: PRODUCTS | AY37: PRODUCTS
B38: IRAS TAX | F38: ORTHO (B+B) | J38: ORTHO (B+B) | N38: ORTHO (B+B) | V38: ORTHO (B+B) | Z38: ORTHO (B+B) | AE38: ORTHO (B+B) | AO38: ORTHO (B+B) | AT38: ORTHO (B+B) | AY38: ORTHO (B+B)
B39: CK SECRETARIAL / ACCOUNTS SERVICES | F39: ABUTMENTS | J39: ABUTMENTS | N39: ABUTMENTS | V39: ABUTMENTS | Z39: ABUTMENTS | AE39: ABUTMENTS | AO39: ABUTMENTS | AT39: ABUTMENTS | AY39: ABUTMENTS
B40: TOWN COUNCIL | C40: 98.1 | F40: IMPLANT | J40: IMPLANT | N40: IMPLANT | V40: IMPLANT | Z40: IMPLANT | AE40: IMPLANT | AO40: IMPLANT | AT40: IMPLANT | AY40: IMPLANT
B41: SERVICE & CONSERVANCY CHARGES | C41: 400 | F41: SKY LAB | J41: SKY LAB | N41: SKY LAB | V41: SKY LAB | Z41: SKY LAB | AE41: SKY LAB | AO41: SKY LAB | AT41: SKY LAB | AY41: SKY LAB
B42: SP | F42: DIGICADCAM | J42: DIGICADCAM | N42: DIGICADCAM | V42: DIGICADCAM | Z42: DIGICADCAM | AE42: DIGICADCAM | AO42: DIGICADCAM | AT42: DIGICADCAM | AY42: DIGICADCAM
B43: SINGTEL | F43: OTHER LAB | J43: OTHER LAB | N43: OTHER LAB | V43: OTHER LAB | Z43: OTHER LAB | AE43: OTHER LAB | AO43: OTHER LAB | AT43: OTHER LAB | AY43: OTHER LAB
...

Sheet HOLLAND SETTLEMENT CALC NEW
A3: MONTH/YEAR: | B3: 46023 | E3: MONTH/YEAR: | F3: =B3 | I3: MONTH/YEAR: | J3: =B3 | M3: MONTH/YEAR: | N3: =B3 | Q3: MONTH/YEAR: | R3: =B3 | U3: MONTH/YEAR: | V3: =B3 | Y3: MONTH/YEAR: | Z3: =B3 | AD3: MONTH/YEAR: | AE3: =B3 | AI3: MONTH/YEAR: | AJ3: =AE3 | AN3: MONTH/YEAR: | AO3: =AE3 | AS3: MONTH/YEAR: | AT3: =AO3 | AX3: MONTH/YEAR: | AY3: =V3
A4: BRANCH: | B4: CASA DENTAL HOLLAND PTE LTD | E4: BRANCH: | F4: =B4 | I4: BRANCH: | J4: =B4 | M4: BRANCH: | N4: =B4 | Q4: BRANCH: | R4: CASA DENTAL AMK PTE LTD | U4: BRANCH: | V4: =B4 | Y4: BRANCH: | Z4: =B4 | AD4: BRANCH: | AE4: =B4 | AI4: BRANCH: | AJ4: CASA DENTAL AMK PTE LTD | AN4: BRANCH: | AO4: =AE4 | AS4: BRANCH: | AT4: =AO4 | AX4: BRANCH: | AY4: =V4
A5: ALL PROVIDERS SETTLEMENT | E5: DR CHAN KC | I5: DR JASMINE LEE | M5: DR ANDREW YIN | Q5: DR KALIE | U5: DR CHARLENE YAP | Y5: DR JEAN CHONG | AD5: DR NG WAN TING | AI5: DR ANDREW YIN | AN5: DR KAREN LEONG | AS5: DR NICHOLAS LIEW | AX5: DR ROLAND FOO
C6: ADMIN CHARGES | G6: ADMIN CHARGES | J6: TOTALS | K6: ADMIN CHARGES | O6: ADMIN CHARGES | S6: ADMIN CHARGES | W6: ADMIN CHARGES | AA6: ADMIN CHARGES | AF6: ADMIN CHARGES | AK6: ADMIN CHARGES | AP6: ADMIN CHARGES | AU6: ADMIN CHARGES | AZ6: ADMIN CHARGES
A7: AIA | C7: =B7*0.05*1.09 | E7: AIA | G7: =F7*0.05*1.09 | I7: AIA | K7: =J7*0.05*1.09 | M7: AIA | O7: =N7*0.05*1.09 | Q7: AIA | S7: =R7*0.05*1.09 | U7: AIA | W7: =V7*0.05*1.09 | Y7: AIA | AA7: =Z7*0.05*1.09 | AD7: AIA | AF7: =AE7*0.05*1.09 | AI7: AIA | AK7: =AJ7*0.05*1.09 | AN7: AIA | AP7: =AO7*0.05*1.09 | AS7: AIA | AU7: =AT7*0.05*1.09 | AX7: AIA | AZ7: =AY7*0.05*1.09
A8: ALLIANCE | C8: =B8*0.05*1.09 | E8: ALLIANCE | G8: =F8*0.05*1.09 | I8: ALLIANCE | K8: =J8*0.05*1.09 | M8: ALLIANCE | O8: =N8*0.05*1.09 | U8: ALLIANCE | W8: =V8*0.05*1.09 | Y8: ALLIANCE | AA8: =Z8*0.05*1.09 | AD8: ALLIANCE | AF8: =AE8*0.05*1.09 | AN8: ALLIANCE | AP8: =AO8*0.05*1.09 | AS8: ALLIANCE | AU8: =AT8*0.05*1.09 | AX8: ALLIANCE | AZ8: =AY8*0.05*1.09
A9: AMEX | C9: =B9*0.0195 | E9: AMEX | G9: =F9*0.0195 | I9: AMEX | K9: =J9*0.0195 | M9: AMEX | O9: =N9*0.0195 | Q9: AMEX | S9: =R9*0.0195 | U9: AMEX | W9: =V9*0.0195 | Y9: AMEX | AA9: =Z9*0.0195 | AD9: AMEX | AF9: =AE9*0.0195 | AI9: AMEX | AK9: =AJ9*0.0195 | AN9: AMEX | AP9: =AO9*0.0195 | AS9: AMEX | AU9: =AT9*0.0195 | AX9: AMEX | AZ9: =AY9*0.0195
A10: BABYBONUS | C10: =B10*0.008 | E10: BABYBONUS | G10: =F10*0.008 | I10: BABYBONUS | K10: =J10*0.008 | M10: BABYBONUS | O10: =N10*0.008 | U10: BABYBONUS | W10: =V10*0.008 | Y10: BABYBONUS | AA10: =Z10*0.008 | AD10: BABYBONUS | AF10: =AE10*0.008 | AN10: BABYBONUS | AP10: =AO10*0.008 | AS10: BABYBONUS | AU10: =AT10*0.008 | AX10: BABYBONUS | AZ10: =AY10*0.008
A11: CASH | E11: CASH | I11: CASH | M11: CASH | Q11: ALLIANCE | S11: =R11*0.05*1.09 | U11: CASH | Y11: CASH | AD11: CASH | AI11: ALLIANCE | AK11: =AJ11*0.05*1.09 | AN11: CASH | AS11: CASH | AX11: CASH
A12: CASA VOUCHER | E12: CASA VOUCHER | I12: CASA VOUCHER | M12: CASA VOUCHER | Q12: CASH | U12: CASA VOUCHER | Y12: CASA VOUCHER | AD12: CASA VOUCHER | AI12: CASH | AN12: CASA VOUCHER | AS12: CASA VOUCHER | AX12: CASA VOUCHER
A13: CDC VOUCHER | E13: CDC VOUCHER | I13: CDC VOUCHER | M13: CDC VOUCHER | Q13: CASA VOUCHER | U13: CDC VOUCHER | Y13: CDC VOUCHER | AD13: CDC VOUCHER | AI13: CASA VOUCHER | AN13: CDC VOUCHER | AS13: CDC VOUCHER | AX13: CDC VOUCHER
A14: CHAS | E14: CHAS | I14: CHAS | M14: CHAS | U14: CHAS | Y14: CHAS | AD14: CHAS | AN14: CHAS | AS14: CHAS | AX14: CHAS
A15: CYNERGY | E15: CYNERGY | I15: CYNERGY | M15: CYNERGY | U15: CYNERGY | Y15: CYNERGY | AD15: CYNERGY | AN15: CYNERGY | AS15: CYNERGY | AX15: CYNERGY
A16: DA ADEPT HEALTH | C16: =B16*8% | E16: DA ADEPT HEALTH | G16: =F16*8% | I16: DA ADEPT HEALTH | K16: =J16*8% | M16: DA ADEPT HEALTH | O16: =N16*8% | U16: DA ADEPT HEALTH | W16: =V16*8% | Y16: DA ADEPT HEALTH | AA16: =Z16*8% | AD16: DA ADEPT HEALTH | AF16: =AE16*8% | AN16: DA ADEPT HEALTH | AP16: =AO16*8% | AS16: DA ADEPT HEALTH | AU16: =AT16*8% | AX16: DA ADEPT HEALTH | AZ16: =AY16*8%
A17: DEPOSIT | C17: =G17+K17+O17+O17+S17+W17+AA17+AF17+AP17+AU17+AZ17 | E17: DEPOSIT | I17: DEPOSIT | M17: DEPOSIT | Q17: DEPOSIT | S17: 0 | U17: DEPOSIT | Y17: DEPOSIT | AD17: DEPOSIT | AI17: DEPOSIT | AN17: DEPOSIT | AS17: DEPOSIT | AX17: DEPOSIT
A18: IHP | C18: =B18*0.051*1.09 | E18: IHP | G18: =F18*0.051*1.09 | I18: IHP | K18: =J18*0.051*1.09 | M18: IHP | O18: =N18*0.051*1.09 | U18: IHP | W18: =V18*0.051*1.09 | Y18: IHP | AA18: =Z18*0.051*1.09 | AD18: IHP | AF18: =AE18*0.051*1.09 | AN18: IHP | AP18: =AO18*0.051*1.09 | AS18: IHP | AU18: =AT18*0.051*1.09 | AX18: IHP | AZ18: =AY18*0.051*1.09
A19: JCB | C19: =B19*0.15*1.09 | E19: JCB | G19: =F19*0.15*1.09 | I19: JCB | K19: =J19*0.15*1.09 | M19: JCB | O19: =N19*0.15*1.09 | U19: JCB | W19: =V19*0.15*1.09 | Y19: JCB | AA19: =Z19*0.15*1.09 | AD19: JCB | AF19: =AE19*0.15*1.09 | AN19: JCB | AP19: =AO19*0.15*1.09 | AS19: JCB | AU19: =AT19*0.15*1.09 | AX19: JCB | AZ19: =AY19*0.15*1.09
A20: MASTER | C20: =B20*0.021 | E20: MASTER | G20: =F20*0.021 | I20: MASTER | K20: =J20*0.021 | M20: MASTER | O20: =N20*0.021 | U20: MASTER | W20: =V20*0.021 | Y20: MASTER | AA20: =Z20*0.021 | AD20: MASTER | AF20: =AE20*0.021 | AN20: MASTER | AP20: =AO20*0.021 | AS20: MASTER | AU20: =AT20*0.021 | AX20: MASTER | AZ20: =AY20*0.021
A21: MEDISAVE | E21: MEDISAVE | I21: MEDISAVE | M21: MEDISAVE | U21: MEDISAVE | Y21: MEDISAVE | AD21: MEDISAVE | AN21: MEDISAVE | AS21: MEDISAVE | AX21: MEDISAVE
A22: mednefits | C22: =B22*20% | E22: mednefits | G22: =F22*20% | I22: mednefits | K22: =J22*20% | M22: mednefits | O22: =N22*20% | U22: mednefits | W22: =V22*20% | Y22: mednefits | AA22: =Z22*20% | AD22: mednefits | AF22: =AE22*20% | AN22: mednefits | AP22: =AO22*20% | AS22: mednefits | AU22: =AT22*20% | AX22: mednefits | AZ22: =AY22*20%
A23: MHC | C23: =B23*0.15*1.09 | E23: MHC | G23: =F23*0.15*1.09 | I23: MHC | K23: =J23*0.15*1.09 | M23: MHC | O23: =N23*0.15*1.09 | U23: MHC | W23: =V23*0.15*1.09 | Y23: MHC | AA23: =Z23*0.15*1.09 | AD23: MHC | AF23: =AE23*0.15*1.09 | AN23: MHC | AP23: =AO23*0.15*1.09 | AS23: MHC | AU23: =AT23*0.15*1.09 | AX23: MHC | AZ23: =AY23*0.15*1.09
A24: NETS | C24: =B24*0.008 | E24: NETS | G24: =F24*0.008 | I24: NETS | K24: =J24*0.008 | M24: NETS | O24: =N24*0.008 | U24: NETS | W24: =V24*0.008 | Y24: NETS | AA24: =Z24*0.008 | AD24: NETS | AF24: =AE24*0.008 | AN24: NETS | AP24: =AO24*0.008 | AS24: NETS | AU24: =AT24*0.008 | AX24: NETS | AZ24: =AY24*0.008
A25: PARKWAY | C25: =B25*10% | E25: PARKWAY | G25: =F25*10% | I25: PARKWAY | K25: =J25*10% | M25: PARKWAY | O25: =N25*10% | U25: PARKWAY | W25: =V25*10% | Y25: PARKWAY | AA25: =Z25*10% | AD25: PARKWAY | AF25: =AE25*10% | AN25: PARKWAY | AP25: =AO25*10% | AS25: PARKWAY | AU25: =AT25*10% | AX25: PARKWAY | AZ25: =AY25*10%
A26: PAYNOW | E26: PAYNOW | I26: PAYNOW | M26: PAYNOW | U26: PAYNOW | Y26: PAYNOW | AD26: PAYNOW | AN26: PAYNOW | AS26: PAYNOW | AX26: PAYNOW
A27: RHI | E27: RHI | I27: RHI | M27: RHI | U27: RHI | Y27: RHI | AD27: RHI | AN27: RHI | AS27: RHI | AX27: RHI
A28: SAH | C28: =B28*8% | E28: SAH | G28: =F28*8% | I28: SAH | K28: =J28*8% | M28: SAH | O28: =N28*8% | U28: SAH | W28: =V28*8% | Y28: SAH | AA28: =Z28*8% | AD28: SAH | AF28: =AE28*8% | AN28: SAH | AP28: =AO28*8% | AS28: SAH | AU28: =AT28*8% | AX28: SAH | AZ28: =AY28*8%
A29: UNION PAY | C29: =B29*2.5% | E29: UNION PAY | G29: =F29*2.5% | I29: UNION PAY | K29: =J29*2.5% | M29: UNION PAY | O29: =N29*2.5% | U29: UNION PAY | W29: =V29*2.5% | Y29: UNION PAY | AA29: =Z29*2.5% | AD29: UNION PAY | AF29: =AE29*2.5% | AN29: UNION PAY | AP29: =AO29*2.5% | AS29: UNION PAY | AU29: =AT29*2.5% | AX29: UNION PAY | AZ29: =AY29*2.5%
A30: VISA | C30: =B30*0.021 | E30: VISA | G30: =F30*0.021 | I30: VISA | K30: =J30*0.021 | M30: VISA | O30: =N30*0.021 | U30: VISA | W30: =V30*0.021 | Y30: VISA | AA30: =Z30*0.021 | AD30: VISA | AF30: =AE30*0.021 | AN30: VISA | AP30: =AO30*0.021 | AS30: VISA | AU30: =AT30*0.021 | AX30: VISA | AZ30: =AY30*0.021
A31: TOTAL INCOME | B31: =SUM(B7:B30) | C31: =SUM(C7:C30) | E31: DR TOTAL INCOME | F31: =SUM(F7:F30) | G31: =SUM(G7:G30) | I31: DR TOTAL INCOME | J31: =SUM(J7:J30) | K31: =SUM(K7:K30) | M31: DR TOTAL INCOME | N31: =SUM(N7:N30) | O31: =SUM(O7:O30) | U31: DR TOTAL INCOME | V31: =SUM(V7:V30) | W31: =SUM(W7:W30) | Y31: DR TOTAL INCOME | Z31: =SUM(Z7:Z30) | AA31: =SUM(AA7:AA30) | AD31: DR TOTAL INCOME | AE31: =SUM(AE7:AE30) | AF31: =SUM(AF7:AF30) | AN31: DR TOTAL INCOME | AO31: =SUM(AO7:AO30) | AP31: =SUM(AP7:AP30) | AS31: DR TOTAL INCOME | AT31: =SUM(AT7:AT30) | AU31: =SUM(AU7:AU30) | AX31: DR TOTAL INCOME | AY31: =SUM(AY7:AY30) | AZ31: =SUM(AZ7:AZ30)
B33: EXPENSES | F33: DEDUCTIONS | H33: REMARKS | J33: DEDUCTIONS | L33: REMARKS | N33: DEDUCTIONS | P33: REMARKS | R33: DEDUCTIONS | T33: REMARKS | V33: DEDUCTIONS | X33: REMARKS | Z33: DEDUCTIONS | AB33: REMARKS | AE33: DEDUCTIONS | AG33: REMARKS | AJ33: DEDUCTIONS | AL33: REMARKS | AO33: DEDUCTIONS | AQ33: REMARKS | AT33: DEDUCTIONS | AV33: REMARKS | AY33: DEDUCTIONS | BA33: REMARKS
B34: ADMIN FEE | C34: =SUM(C7:C30) | F34: ADMIN CHARGES | G34: =G31 | J34: ADMIN CHARGES | K34: =K31 | N34: ADMIN CHARGES | O34: =O31 | R34: ADMIN CHARGES | S34: =#REF! | V34: ADMIN CHARGES | W34: =W31 | Z34: ADMIN CHARGES | AA34: =AA31 | AE34: ADMIN CHARGES | AF34: =AF31 | AJ34: ADMIN CHARGES | AK34: =#REF! | AO34: ADMIN CHARGES | AP34: =AP31 | AT34: ADMIN CHARGES | AU34: =AU31 | AY34: ADMIN CHARGES | AZ34: =AZ31
B35: GST | C35: =K35+O35+AA35+AF35+AM35+AP35+T35+W35+AU35+AZ35 | F35: GST | J35: GST | N35: GST | R35: GST | V35: GST | Z35: GST | AE35: GST | AJ35: GST | AO35: GST | AT35: GST | AY35: GST
B36: RENTAL | F36: ICC-5 | J36: ICC-5 | N36: ICC-5 | V36: ICC-5 | Z36: ICC-5 | AE36: ICC-5 | AO36: ICC-5 | AT36: ICC-5 | AY36: ICC-5
B37: LOAN INTEREST | F37: PRODUCTS | J37: PRODUCTS | N37: PRODUCTS | V37: PRODUCTS | Z37: PRODUCTS | AE37: PRODUCTS | AO37: PRODUCTS | AT37: PRODUCTS | AY37: PRODUCTS
B38: IRAS TAX | C38: 22590 | D38: NOV 2025 $45215 | F38: ORTHO (B+B) | J38: ORTHO (B+B) | N38: ORTHO (B+B) | V38: ORTHO (B+B) | Z38: ORTHO (B+B) | AE38: ORTHO (B+B) | AO38: ORTHO (B+B) | AT38: ORTHO (B+B) | AY38: ORTHO (B+B)
B39: CK SECRETARIAL / ACCOUNTS SERVICES | D39: DEC25-MAR26 $22590 | F39: ABUTMENTS | J39: ABUTMENTS | N39: ABUTMENTS | V39: ABUTMENTS | Z39: ABUTMENTS | AE39: ABUTMENTS | AO39: ABUTMENTS | AT39: ABUTMENTS | AY39: ABUTMENTS
B40: TOWN COUNCIL | C40: 286.13 | F40: IMPLANT | J40: IMPLANT | N40: IMPLANT | V40: IMPLANT | Z40: IMPLANT | AE40: IMPLANT | AO40: IMPLANT | AT40: IMPLANT | AY40: IMPLANT
B41: SERVICE & CONSERVANCY CHARGES | C41: 800 | F41: SKY LAB | J41: SKY LAB | N41: SKY LAB | V41: SKY LAB | Z41: SKY LAB | AE41: SKY LAB | AO41: SKY LAB | AT41: SKY LAB | AY41: SKY LAB
B42: SP | F42: DIGICADCAM | J42: DIGICADCAM | N42: DIGICADCAM | V42: DIGICADCAM | Z42: DIGICADCAM | AE42: DIGICADCAM | AO42: DIGICADCAM | AT42: DIGICADCAM | AY42: DIGICADCAM
B43: SINGTEL | F43: OTHER LAB | J43: OTHER LAB | N43: OTHER LAB | V43: OTHER LAB | Z43: OTHER LAB | AE43: OTHER LAB | AO43: OTHER LAB | AT43: OTHER LAB | AY43: OTHER LAB
...

Sheet ADM SETTLEMENT CALC NEW
A3: MONTH/YEAR: | B3: 46023 | E3: MONTH/YEAR: | F3: =B3 | I3: MONTH/YEAR: | J3: =B3 | M3: MONTH/YEAR: | N3: =B3 | Q3: MONTH/YEAR: | R3: =B3 | U3: MONTH/YEAR: | V3: =B3 | Y3: MONTH/YEAR: | Z3: =B3 | AD3: MONTH/YEAR: | AE3: =B3 | AI3: MONTH/YEAR: | AJ3: =AE3 | AN3: MONTH/YEAR: | AO3: =AE3 | AS3: MONTH/YEAR: | AT3: =AO3 | AX3: MONTH/YEAR: | AY3: =V3
A4: BRANCH: | B4: CASA DENTAL ADMIRALTY | E4: BRANCH: | F4: =B4 | I4: BRANCH: | J4: =B4 | M4: BRANCH: | N4: =B4 | Q4: BRANCH: | R4: CASA DENTAL AMK PTE LTD | U4: BRANCH: | V4: =B4 | Y4: BRANCH: | Z4: =B4 | AD4: BRANCH: | AE4: =B4 | AI4: BRANCH: | AJ4: CASA DENTAL AMK PTE LTD | AN4: BRANCH: | AO4: =AE4 | AS4: BRANCH: | AT4: =AO4 | AX4: BRANCH: | AY4: =V4
A5: ALL PROVIDERS SETTLEMENT | E5: DR CHAN KC | I5: DR CHAN CHIEN CHI | M5: DR CELINE TEO | Q5: DR KALIE | U5: DR KEEFE SIM | Y5: DR JENNIFER HOANG | AD5: DR HUANG JIAWEN | AI5: DR ANDREW YIN | AN5: DR YVETTE CHOW | AS5: DR PETER KEITH | AX5: DR ROLAND FOO
C6: ADMIN CHARGES | G6: ADMIN CHARGES | K6: ADMIN CHARGES | O6: ADMIN CHARGES | S6: ADMIN CHARGES | W6: ADMIN CHARGES | AA6: ADMIN CHARGES | AF6: ADMIN CHARGES | AK6: ADMIN CHARGES | AP6: ADMIN CHARGES | AU6: ADMIN CHARGES | AZ6: ADMIN CHARGES
A7: AIA | C7: =B7*0.05*1.09 | E7: AIA | G7: =F7*0.05*1.09 | I7: AIA | K7: =J7*0.05*1.09 | M7: AIA | O7: =N7*0.05*1.09 | Q7: AIA | S7: =R7*0.05*1.09 | U7: AIA | W7: =V7*0.05*1.09 | Y7: AIA | AA7: =Z7*0.05*1.09 | AD7: AIA | AF7: =AE7*0.05*1.09 | AI7: AIA | AK7: =AJ7*0.05*1.09 | AN7: AIA | AP7: =AO7*0.05*1.09 | AS7: AIA | AU7: =AT7*0.05*1.09 | AX7: AIA | AZ7: =AY7*0.05*1.09
A8: ALLIANCE | C8: =B8*0.05*1.09 | E8: ALLIANCE | G8: =F8*0.05*1.09 | I8: ALLIANCE | K8: =J8*0.05*1.09 | M8: ALLIANCE | O8: =N8*0.05*1.09 | U8: ALLIANCE | W8: =V8*0.05*1.09 | Y8: ALLIANCE | AA8: =Z8*0.05*1.09 | AD8: ALLIANCE | AF8: =AE8*0.05*1.09 | AN8: ALLIANCE | AP8: =AO8*0.05*1.09 | AS8: ALLIANCE | AU8: =AT8*0.05*1.09 | AX8: ALLIANCE | AZ8: =AY8*0.05*1.09
A9: AMEX | C9: =B9*0.0195 | E9: AMEX | G9: =F9*0.0195 | I9: AMEX | K9: =J9*0.0195 | M9: AMEX | O9: =N9*0.0195 | Q9: AMEX | S9: =R9*0.0195 | U9: AMEX | W9: =V9*0.0195 | Y9: AMEX | AA9: =Z9*0.0195 | AD9: AMEX | AF9: =AE9*0.0195 | AI9: AMEX | AK9: =AJ9*0.0195 | AN9: AMEX | AP9: =AO9*0.0195 | AS9: AMEX | AU9: =AT9*0.0195 | AX9: AMEX | AZ9: =AY9*0.0195
A10: BABYBONUS | C10: =B10*0.008 | E10: BABYBONUS | G10: =F10*0.008 | I10: BABYBONUS | K10: =J10*0.008 | M10: BABYBONUS | O10: =N10*0.008 | U10: BABYBONUS | W10: =V10*0.008 | Y10: BABYBONUS | AA10: =Z10*0.008 | AD10: BABYBONUS | AF10: =AE10*0.008 | AN10: BABYBONUS | AP10: =AO10*0.008 | AS10: BABYBONUS | AU10: =AT10*0.008 | AX10: BABYBONUS | AZ10: =AY10*0.008
A11: CASH | E11: CASH | I11: CASH | M11: CASH | Q11: ALLIANCE | S11: =R11*0.05*1.09 | U11: CASH | Y11: CASH | AD11: CASH | AI11: ALLIANCE | AK11: =AJ11*0.05*1.09 | AN11: CASH | AS11: CASH | AX11: CASH
A12: CASA VOUCHER | E12: CASA VOUCHER | I12: CASA VOUCHER | M12: CASA VOUCHER | Q12: CASH | U12: CASA VOUCHER | Y12: CASA VOUCHER | AD12: CASA VOUCHER | AI12: CASH | AN12: CASA VOUCHER | AS12: CASA VOUCHER | AX12: CASA VOUCHER
A13: CDC VOUCHER | E13: CDC VOUCHER | I13: CDC VOUCHER | M13: CDC VOUCHER | Q13: CASA VOUCHER | U13: CDC VOUCHER | Y13: CDC VOUCHER | AD13: CDC VOUCHER | AI13: CASA VOUCHER | AN13: CDC VOUCHER | AS13: CDC VOUCHER | AX13: CDC VOUCHER
A14: CHAS | E14: CHAS | I14: CHAS | M14: CHAS | U14: CHAS | Y14: CHAS | AD14: CHAS | AN14: CHAS | AS14: CHAS | AX14: CHAS
A15: CYNERGY | E15: CYNERGY | I15: CYNERGY | M15: CYNERGY | U15: CYNERGY | Y15: CYNERGY | AD15: CYNERGY | AN15: CYNERGY | AS15: CYNERGY | AX15: CYNERGY
A16: DA ADEPT HEALTH | C16: =B16*8% | E16: DA ADEPT HEALTH | G16: =F16*8% | I16: DA ADEPT HEALTH | K16: =J16*8% | M16: DA ADEPT HEALTH | O16: =N16*8% | U16: DA ADEPT HEALTH | W16: =V16*8% | Y16: DA ADEPT HEALTH | AA16: =Z16*8% | AD16: DA ADEPT HEALTH | AF16: =AE16*8% | AN16: DA ADEPT HEALTH | AP16: =AO16*8% | AS16: DA ADEPT HEALTH | AU16: =AT16*8% | AX16: DA ADEPT HEALTH | AZ16: =AY16*8%
A17: DEPOSIT | C17: =G17+K17+O17+O17+S17+W17+AA17+AF17+AP17+AU17+AZ17 | E17: DEPOSIT | I17: DEPOSIT | M17: DEPOSIT | Q17: DEPOSIT | S17: 0 | U17: DEPOSIT | Y17: DEPOSIT | AD17: DEPOSIT | AI17: DEPOSIT | AN17: DEPOSIT | AS17: DEPOSIT | AX17: DEPOSIT
A18: IHP | C18: =B18*0.051*1.09 | E18: IHP | G18: =F18*0.051*1.09 | I18: IHP | K18: =J18*0.051*1.09 | M18: IHP | O18: =N18*0.051*1.09 | U18: IHP | W18: =V18*0.051*1.09 | Y18: IHP | AA18: =Z18*0.051*1.09 | AD18: IHP | AF18: =AE18*0.051*1.09 | AN18: IHP | AP18: =AO18*0.051*1.09 | AS18: IHP | AU18: =AT18*0.051*1.09 | AX18: IHP | AZ18: =AY18*0.051*1.09
A19: JCB | C19: =B19*0.15*1.09 | E19: JCB | G19: =F19*0.15*1.09 | I19: JCB | K19: =J19*0.15*1.09 | M19: JCB | O19: =N19*0.15*1.09 | U19: JCB | W19: =V19*0.15*1.09 | Y19: JCB | AA19: =Z19*0.15*1.09 | AD19: JCB | AF19: =AE19*0.15*1.09 | AN19: JCB | AP19: =AO19*0.15*1.09 | AS19: JCB | AU19: =AT19*0.15*1.09 | AX19: JCB | AZ19: =AY19*0.15*1.09
A20: MASTER | C20: =B20*0.021 | E20: MASTER | G20: =F20*0.021 | I20: MASTER | K20: =J20*0.021 | M20: MASTER | O20: =N20*0.021 | U20: MASTER | W20: =V20*0.021 | Y20: MASTER | AA20: =Z20*0.021 | AD20: MASTER | AF20: =AE20*0.021 | AN20: MASTER | AP20: =AO20*0.021 | AS20: MASTER | AU20: =AT20*0.021 | AX20: MASTER | AZ20: =AY20*0.021
A21: MEDISAVE | E21: MEDISAVE | I21: MEDISAVE | M21: MEDISAVE | U21: MEDISAVE | Y21: MEDISAVE | AD21: MEDISAVE | AN21: MEDISAVE | AS21: MEDISAVE | AX21: MEDISAVE
A22: mednefits | C22: =B22*20% | E22: mednefits | G22: =F22*20% | I22: mednefits | K22: =J22*20% | M22: mednefits | O22: =N22*20% | U22: mednefits | W22: =V22*20% | Y22: mednefits | AA22: =Z22*20% | AD22: mednefits | AF22: =AE22*20% | AN22: mednefits | AP22: =AO22*20% | AS22: mednefits | AU22: =AT22*20% | AX22: mednefits | AZ22: =AY22*20%
A23: MHC | C23: =B23*0.15*1.09 | E23: MHC | G23: =F23*0.15*1.09 | I23: MHC | K23: =J23*0.15*1.09 | M23: MHC | O23: =N23*0.15*1.09 | U23: MHC | W23: =V23*0.15*1.09 | Y23: MHC | AA23: =Z23*0.15*1.09 | AD23: MHC | AF23: =AE23*0.15*1.09 | AN23: MHC | AP23: =AO23*0.15*1.09 | AS23: MHC | AU23: =AT23*0.15*1.09 | AX23: MHC | AZ23: =AY23*0.15*1.09
A24: NETS | C24: =B24*0.008 | E24: NETS | G24: =F24*0.008 | I24: NETS | K24: =J24*0.008 | M24: NETS | O24: =N24*0.008 | U24: NETS | W24: =V24*0.008 | Y24: NETS | AA24: =Z24*0.008 | AD24: NETS | AF24: =AE24*0.008 | AN24: NETS | AP24: =AO24*0.008 | AS24: NETS | AU24: =AT24*0.008 | AX24: NETS | AZ24: =AY24*0.008
A25: PARKWAY | C25: =B25*10% | E25: PARKWAY | G25: =F25*10% | I25: PARKWAY | K25: =J25*10% | M25: PARKWAY | O25: =N25*10% | U25: PARKWAY | W25: =V25*10% | Y25: PARKWAY | AA25: =Z25*10% | AD25: PARKWAY | AF25: =AE25*10% | AN25: PARKWAY | AP25: =AO25*10% | AS25: PARKWAY | AU25: =AT25*10% | AX25: PARKWAY | AZ25: =AY25*10%
A26: PAYNOW | E26: PAYNOW | I26: PAYNOW | M26: PAYNOW | U26: PAYNOW | Y26: PAYNOW | AD26: PAYNOW | AN26: PAYNOW | AS26: PAYNOW | AX26: PAYNOW
A27: RHI | E27: RHI | I27: RHI | M27: RHI | U27: RHI | Y27: RHI | AD27: RHI | AN27: RHI | AS27: RHI | AX27: RHI
A28: SAH | C28: =B28*8% | E28: SAH | G28: =F28*8% | I28: SAH | K28: =J28*8% | M28: SAH | O28: =N28*8% | U28: SAH | W28: =V28*8% | Y28: SAH | AA28: =Z28*8% | AD28: SAH | AF28: =AE28*8% | AN28: SAH | AP28: =AO28*8% | AS28: SAH | AU28: =AT28*8% | AX28: SAH | AZ28: =AY28*8%
A29: UNION PAY | C29: =B29*2.5% | E29: UNION PAY | G29: =F29*2.5% | I29: UNION PAY | K29: =J29*2.5% | M29: UNION PAY | O29: =N29*2.5% | U29: UNION PAY | W29: =V29*2.5% | Y29: UNION PAY | AA29: =Z29*2.5% | AD29: UNION PAY | AF29: =AE29*2.5% | AN29: UNION PAY | AP29: =AO29*2.5% | AS29: UNION PAY | AU29: =AT29*2.5% | AX29: UNION PAY | AZ29: =AY29*2.5%
A30: VISA | C30: =B30*0.021 | E30: VISA | G30: =F30*0.021 | I30: VISA | K30: =J30*0.021 | M30: VISA | O30: =N30*0.021 | U30: VISA | W30: =V30*0.021 | Y30: VISA | AA30: =Z30*0.021 | AD30: VISA | AF30: =AE30*0.021 | AN30: VISA | AP30: =AO30*0.021 | AS30: VISA | AU30: =AT30*0.021 | AX30: VISA | AZ30: =AY30*0.021
A31: TOTAL INCOME | B31: =SUM(B7:B30) | C31: =SUM(C7:C30) | E31: DR TOTAL INCOME | F31: =SUM(F7:F30) | G31: =SUM(G7:G30) | I31: DR TOTAL INCOME | J31: =SUM(J7:J30) | K31: =SUM(K7:K30) | M31: DR TOTAL INCOME | N31: =SUM(N7:N30) | O31: =SUM(O7:O30) | U31: DR TOTAL INCOME | V31: =SUM(V7:V30) | W31: =SUM(W7:W30) | Y31: DR TOTAL INCOME | Z31: =SUM(Z7:Z30) | AA31: =SUM(AA7:AA30) | AD31: DR TOTAL INCOME | AE31: =SUM(AE7:AE30) | AF31: =SUM(AF7:AF30) | AN31: DR TOTAL INCOME | AO31: =SUM(AO7:AO30) | AP31: =SUM(AP7:AP30) | AS31: DR TOTAL INCOME | AT31: =SUM(AT7:AT30) | AU31: =SUM(AU7:AU30) | AX31: DR TOTAL INCOME | AY31: =SUM(AY7:AY30) | AZ31: =SUM(AZ7:AZ30)
B33: EXPENSES | F33: DEDUCTIONS | H33: REMARKS | J33: DEDUCTIONS | L33: REMARKS | N33: DEDUCTIONS | P33: REMARKS | R33: DEDUCTIONS | T33: REMARKS | V33: DEDUCTIONS | X33: REMARKS | Z33: DEDUCTIONS | AB33: REMARKS | AE33: DEDUCTIONS | AG33: REMARKS | AJ33: DEDUCTIONS | AL33: REMARKS | AO33: DEDUCTIONS | AQ33: REMARKS | AT33: DEDUCTIONS | AV33: REMARKS | AY33: DEDUCTIONS | BA33: REMARKS
B34: ADMIN FEE | C34: =SUM(C7:C30) | F34: ADMIN CHARGES | G34: =G31 | J34: ADMIN CHARGES | K34: =K31 | N34: ADMIN CHARGES | O34: =O31 | R34: ADMIN CHARGES | S34: =#REF! | V34: ADMIN CHARGES | W34: =W31 | Z34: ADMIN CHARGES | AA34: =AA31 | AE34: ADMIN CHARGES | AF34: =AF31 | AJ34: ADMIN CHARGES | AK34: =#REF! | AO34: ADMIN CHARGES | AP34: =AP31 | AT34: ADMIN CHARGES | AU34: =AU31 | AY34: ADMIN CHARGES | AZ34: =AZ31
B35: GST | C35: =K35+O35+AA35+AF35+AM35+AP35+T35+W35+AU35+AZ35 | F35: GST | J35: GST | N35: GST | R35: GST | V35: GST | Z35: GST | AE35: GST | AJ35: GST | AO35: GST | AT35: GST | AY35: GST
B36: RENTAL | F36: ICC-5 | J36: ICC-5 | N36: ICC-5 | V36: ICC-5 | Z36: ICC-5 | AE36: ICC-5 | AO36: ICC-5 | AT36: ICC-5 | AY36: ICC-5
B37: LOAN INTEREST | F37: PRODUCTS | J37: PRODUCTS | N37: PRODUCTS | V37: PRODUCTS | Z37: PRODUCTS | AE37: PRODUCTS | AO37: PRODUCTS | AT37: PRODUCTS | AY37: PRODUCTS
B38: IRAS TAX | C38: 181.05 | D38: JAN 181.05 | F38: ORTHO (B+B) | J38: ORTHO (B+B) | N38: ORTHO (B+B) | V38: ORTHO (B+B) | Z38: ORTHO (B+B) | AE38: ORTHO (B+B) | AO38: ORTHO (B+B) | AT38: ORTHO (B+B) | AY38: ORTHO (B+B)
B39: CK SECRETARIAL / ACCOUNTS SERVICES | D39: FEB 50895 | F39: ABUTMENTS | J39: ABUTMENTS | N39: ABUTMENTS | V39: ABUTMENTS | Z39: ABUTMENTS | AE39: ABUTMENTS | AO39: ABUTMENTS | AT39: ABUTMENTS | AY39: ABUTMENTS
B40: TOWN COUNCIL | C40: 286.13 | D40: MAR-JUN 25420 | F40: IMPLANT | J40: IMPLANT | N40: IMPLANT | V40: IMPLANT | Z40: IMPLANT | AE40: IMPLANT | AO40: IMPLANT | AT40: IMPLANT | AY40: IMPLANT
B41: SERVICE & CONSERVANCY CHARGES | C41: 800 | F41: SKY LAB | J41: SKY LAB | N41: SKY LAB | V41: SKY LAB | Z41: SKY LAB | AE41: SKY LAB | AO41: SKY LAB | AT41: SKY LAB | AY41: SKY LAB
B42: SP | F42: DIGICADCAM | J42: DIGICADCAM | N42: DIGICADCAM | V42: DIGICADCAM | Z42: DIGICADCAM | AE42: DIGICADCAM | AO42: DIGICADCAM | AT42: DIGICADCAM | AY42: DIGICADCAM
B43: SINGTEL | F43: OTHER LAB | J43: OTHER LAB | N43: OTHER LAB | V43: OTHER LAB | Z43: OTHER LAB | AE43: OTHER LAB | AO43: OTHER LAB | AT43: OTHER LAB | AY43: OTHER LAB
...

Sheet BB SETTLEMENT CALC NEW
A3: MONTH/YEAR: | B3: 46023 | E3: MONTH/YEAR: | F3: =B3 | I3: MONTH/YEAR: | J3: =B3 | M3: MONTH/YEAR: | N3: =B3 | Q3: MONTH/YEAR: | R3: =B3 | U3: MONTH/YEAR: | V3: =B3 | Y3: MONTH/YEAR: | Z3: =B3 | AD3: MONTH/YEAR: | AE3: =B3 | AI3: MONTH/YEAR: | AJ3: =AE3
A4: BRANCH: | B4: CASA DENTAL BUKIT BATOK PTE LTD | E4: BRANCH: | F4: =B4 | I4: BRANCH: | J4: =F4 | M4: BRANCH: | N4: =J4 | Q4: BRANCH: | R4: CASA DENTAL AMK PTE LTD | U4: BRANCH: | V4: =N4 | Y4: BRANCH: | Z4: =V4 | AD4: BRANCH: | AE4: =Z4 | AI4: BRANCH: | AJ4: CASA DENTAL AMK PTE LTD
A5: ALL PROVIDERS SETTLEMENT | E5: DR ANGELA TRAN | I5: DR JENNIFER HOANG | M5: DR KALIE CHIA | Q5: DR KALIE | U5: DR YVETTE CHOW | Y5: DR PETER KEITH | AD5: DR NICHOLAS LIEW | AI5: DR ANDREW YIN
C6: ADMIN CHARGES | G6: ADMIN CHARGES | J6: TOTALS | K6: ADMIN CHARGES | O6: ADMIN CHARGES | S6: ADMIN CHARGES | W6: ADMIN CHARGES | AA6: ADMIN CHARGES | AF6: ADMIN CHARGES | AK6: ADMIN CHARGES
A7: AIA | C7: =B7*0.05*1.09 | E7: AIA | G7: =F7*0.05*1.09 | I7: AIA | K7: =J7*0.05*1.09 | M7: AIA | O7: =N7*0.05*1.09 | Q7: AIA | S7: =R7*0.05*1.09 | U7: AIA | W7: =V7*0.05*1.09 | Y7: AIA | AA7: =Z7*0.05*1.09 | AD7: AIA | AF7: =AE7*0.05*1.09 | AI7: AIA | AK7: =AJ7*0.05*1.09
A8: ALLIANCE | C8: =B8*0.05*1.09 | E8: ALLIANCE | G8: =F8*0.05*1.09 | I8: ALLIANCE | K8: =J8*0.05*1.09 | M8: ALLIANCE | O8: =N8*0.05*1.09 | U8: ALLIANCE | W8: =V8*0.05*1.09 | Y8: ALLIANCE | AA8: =Z8*0.05*1.09 | AD8: ALLIANCE | AF8: =AE8*0.05*1.09
A9: AMEX | C9: =B9*0.0195 | E9: AMEX | G9: =F9*0.0195 | I9: AMEX | K9: =J9*0.0195 | M9: AMEX | O9: =N9*0.0195 | Q9: AMEX | S9: =R9*0.0195 | U9: AMEX | W9: =V9*0.0195 | Y9: AMEX | AA9: =Z9*0.0195 | AD9: AMEX | AF9: =AE9*0.0195 | AI9: AMEX | AK9: =AJ9*0.0195
A10: BABYBONUS | C10: =B10*0.008 | E10: BABYBONUS | G10: =F10*0.008 | I10: BABYBONUS | K10: =J10*0.008 | M10: BABYBONUS | O10: =N10*0.008 | U10: BABYBONUS | W10: =V10*0.008 | Y10: BABYBONUS | AA10: =Z10*0.008 | AD10: BABYBONUS | AF10: =AE10*0.008
A11: CASH | E11: CASH | I11: CASH | M11: CASH | Q11: ALLIANCE | S11: =R11*0.05*1.09 | U11: CASH | Y11: CASH | AD11: CASH | AI11: ALLIANCE | AK11: =AJ11*0.05*1.09
A12: CASA VOUCHER | E12: CASA VOUCHER | I12: CASA VOUCHER | M12: CASA VOUCHER | Q12: CASH | U12: CASA VOUCHER | Y12: CASA VOUCHER | AD12: CASA VOUCHER | AI12: CASH
A13: CDC VOUCHER | E13: CDC VOUCHER | I13: CDC VOUCHER | M13: CDC VOUCHER | Q13: CASA VOUCHER | U13: CDC VOUCHER | Y13: CDC VOUCHER | AD13: CDC VOUCHER | AI13: CASA VOUCHER
A14: CHAS | E14: CHAS | I14: CHAS | M14: CHAS | U14: CHAS | Y14: CHAS | AD14: CHAS
A15: CYNERGY | E15: CYNERGY | I15: CYNERGY | M15: CYNERGY | U15: CYNERGY | Y15: CYNERGY | AD15: CYNERGY
A16: DA ADEPT HEALTH | C16: =B16*8% | E16: DA ADEPT HEALTH | G16: =F16*8% | I16: DA ADEPT HEALTH | K16: =J16*8% | M16: DA ADEPT HEALTH | O16: =N16*8% | U16: DA ADEPT HEALTH | W16: =V16*8% | Y16: DA ADEPT HEALTH | AA16: =Z16*8% | AD16: DA ADEPT HEALTH | AF16: =AE16*8%
A17: DEPOSIT | C17: =G17+K17+O17+O17+S17+W17+AA17+AF17 | E17: DEPOSIT | I17: DEPOSIT | M17: DEPOSIT | Q17: DEPOSIT | S17: 0 | U17: DEPOSIT | Y17: DEPOSIT | AD17: DEPOSIT | AI17: DEPOSIT
A18: IHP | C18: =B18*0.051*1.09 | E18: IHP | G18: =F18*0.051*1.09 | I18: IHP | K18: =J18*0.051*1.09 | M18: IHP | O18: =N18*0.051*1.09 | U18: IHP | W18: =V18*0.051*1.09 | Y18: IHP | AA18: =Z18*0.051*1.09 | AD18: IHP | AF18: =AE18*0.051*1.09
A19: JCB | C19: =B19*0.15*1.09 | E19: JCB | G19: =F19*0.15*1.09 | I19: JCB | K19: =J19*0.15*1.09 | M19: JCB | O19: =N19*0.15*1.09 | U19: JCB | W19: =V19*0.15*1.09 | Y19: JCB | AA19: =Z19*0.15*1.09 | AD19: JCB | AF19: =AE19*0.15*1.09
A20: MASTER | C20: =B20*0.0225 | E20: MASTER | G20: =F20*0.0225 | I20: MASTER | K20: =J20*0.0225 | M20: MASTER | O20: =N20*0.0225 | U20: MASTER | W20: =V20*0.0225 | Y20: MASTER | AA20: =Z20*0.0225 | AD20: MASTER | AF20: =AE20*0.0225
A21: MEDISAVE | E21: MEDISAVE | I21: MEDISAVE | M21: MEDISAVE | U21: MEDISAVE | Y21: MEDISAVE | AD21: MEDISAVE
A22: mednefits | C22: =B22*20% | E22: mednefits | G22: =F22*20% | I22: mednefits | K22: =J22*20% | M22: mednefits | O22: =N22*20% | U22: mednefits | W22: =V22*20% | Y22: mednefits | AA22: =Z22*20% | AD22: mednefits | AF22: =AE22*20%
A23: MHC | C23: =B23*0.15*1.09 | E23: MHC | G23: =F23*0.15*1.09 | I23: MHC | K23: =J23*0.15*1.09 | M23: MHC | O23: =N23*0.15*1.09 | U23: MHC | W23: =V23*0.15*1.09 | Y23: MHC | AA23: =Z23*0.15*1.09 | AD23: MHC | AF23: =AE23*0.15*1.09
A24: NETS | C24: =B24*0.008 | E24: NETS | G24: =F24*0.008 | I24: NETS | K24: =J24*0.008 | M24: NETS | O24: =N24*0.008 | U24: NETS | W24: =V24*0.008 | Y24: NETS | AA24: =Z24*0.008 | AD24: NETS | AF24: =AE24*0.008
A25: PARKWAY | C25: =B25*10% | E25: PARKWAY | G25: =F25*10% | I25: PARKWAY | K25: =J25*10% | M25: PARKWAY | O25: =N25*10% | U25: PARKWAY | W25: =V25*10% | Y25: PARKWAY | AA25: =Z25*10% | AD25: PARKWAY | AF25: =AE25*10%
A26: PAYNOW | E26: PAYNOW | I26: PAYNOW | M26: PAYNOW | U26: PAYNOW | Y26: PAYNOW | AD26: PAYNOW
A27: RHI | E27: RHI | I27: RHI | M27: RHI | U27: RHI | Y27: RHI | AD27: RHI
A28: SAH | C28: =B28*8% | E28: SAH | G28: =F28*8% | I28: SAH | K28: =J28*8% | M28: SAH | O28: =N28*8% | U28: SAH | W28: =V28*8% | Y28: SAH | AA28: =Z28*8% | AD28: SAH | AF28: =AE28*8%
A29: UNION PAY | C29: =B29*2.5% | E29: UNION PAY | G29: =F29*2.5% | I29: UNION PAY | K29: =J29*2.5% | M29: UNION PAY | O29: =N29*2.5% | U29: UNION PAY | W29: =V29*2.5% | Y29: UNION PAY | AA29: =Z29*2.5% | AD29: UNION PAY | AF29: =AE29*2.5%
A30: VISA | C30: =B30*0.0225 | E30: VISA | G30: =F30*0.0225 | I30: VISA | K30: =J30*0.0225 | M30: VISA | O30: =N30*0.0225 | U30: VISA | W30: =V30*0.0225 | Y30: VISA | AA30: =Z30*0.0225 | AD30: VISA | AF30: =AE30*0.0225
A31: TOTAL INCOME | B31: =SUM(B7:B30) | C31: =SUM(C7:C30) | E31: DR TOTAL INCOME | F31: =SUM(F7:F30) | G31: =SUM(G7:G30) | I31: DR TOTAL INCOME | J31: =SUM(J7:J30) | K31: =SUM(K7:K30) | M31: DR TOTAL INCOME | N31: =SUM(N7:N30) | O31: =SUM(O7:O30) | U31: DR TOTAL INCOME | V31: =SUM(V7:V30) | W31: =SUM(W7:W30) | Y31: DR TOTAL INCOME | Z31: =SUM(Z7:Z30) | AA31: =SUM(AA7:AA30) | AD31: DR TOTAL INCOME | AE31: =SUM(AE7:AE30) | AF31: =SUM(AF7:AF30)
B33: EXPENSES | F33: DEDUCTIONS | H33: REMARKS | J33: DEDUCTIONS | L33: REMARKS | N33: DEDUCTIONS | P33: REMARKS | R33: DEDUCTIONS | T33: REMARKS | V33: DEDUCTIONS | X33: REMARKS | Z33: DEDUCTIONS | AB33: REMARKS | AE33: DEDUCTIONS | AG33: REMARKS | AJ33: DEDUCTIONS | AL33: REMARKS
B34: ADMIN FEE | C34: =SUM(C7:C30) | F34: ADMIN CHARGES | G34: =G31 | J34: ADMIN CHARGES | K34: =K31 | N34: ADMIN CHARGES | O34: =O31 | R34: ADMIN CHARGES | S34: =#REF! | V34: ADMIN CHARGES | W34: =W31 | Z34: ADMIN CHARGES | AA34: =AA31 | AE34: ADMIN CHARGES | AF34: =AF31 | AJ34: ADMIN CHARGES | AK34: =#REF!
B35: GST | C35: =G35+K35+O35+S35+W35+AA35+AF35+AK35 | F35: GST | J35: GST | N35: GST | R35: GST | V35: GST | Z35: GST | AE35: GST | AJ35: GST
B36: RENTAL | F36: ICC-5 | J36: ICC-5 | N36: ICC-5 | V36: ICC-5 | Z36: ICC-5 | AE36: ICC-5
B37: LOAN INTEREST | C37: 22.12 | F37: PRODUCTS | J37: PRODUCTS | N37: PRODUCTS | V37: PRODUCTS | Z37: PRODUCTS | AE37: PRODUCTS
B38: IRAS TAX | C38: 12386.28 | D38: 46023 | F38: ORTHO (B+B) | J38: ORTHO (B+B) | N38: ORTHO (B+B) | V38: ORTHO (B+B) | Z38: ORTHO (B+B) | AE38: ORTHO (B+B)
B39: CK SECRETARIAL / ACCOUNTS SERVICES | D39: 12386.28 | F39: ABUTMENTS | J39: ABUTMENTS | N39: ABUTMENTS | V39: ABUTMENTS | Z39: ABUTMENTS | AE39: ABUTMENTS
B40: TOWN COUNCIL | F40: IMPLANT | J40: IMPLANT | N40: IMPLANT | V40: IMPLANT | Z40: IMPLANT | AE40: IMPLANT
B41: SERVICE & CONSERVANCY CHARGES | F41: SKY LAB | J41: SKY LAB | N41: SKY LAB | V41: SKY LAB | Z41: SKY LAB | AE41: SKY LAB
B42: SP | F42: DIGICADCAM | J42: DIGICADCAM | N42: DIGICADCAM | V42: DIGICADCAM | Z42: DIGICADCAM | AE42: DIGICADCAM
B43: SINGTEL | F43: OTHER LAB | J43: OTHER LAB | N43: OTHER LAB | V43: OTHER LAB | Z43: OTHER LAB | AE43: OTHER LAB
...

Sheet WDLS SETTLEMENT CAL NEW
A3: MONTH/YEAR: | B3: 46023 | E3: MONTH/YEAR: | F3: =B3 | I3: MONTH/YEAR: | J3: =B3 | M3: MONTH/YEAR: | N3: =B3 | Q3: MONTH/YEAR: | R3: =B3 | U3: MONTH/YEAR: | V3: =B3 | Y3: MONTH/YEAR: | Z3: =B3 | AD3: MONTH/YEAR: | AE3: =B3 | AI3: MONTH/YEAR: | AJ3: =AE3 | AN3: MONTH/YEAR: | AO3: =AE3 | AS3: MONTH/YEAR: | AT3: =AO3 | AX3: MONTH/YEAR: | AY3: =V3
A4: BRANCH: | B4: CASA DENTAL WOODLANDS PTE LTD | E4: BRANCH: | F4: =B4 | I4: BRANCH: | J4: =B4 | M4: BRANCH: | N4: =B4 | Q4: BRANCH: | R4: CASA DENTAL AMK PTE LTD | U4: BRANCH: | V4: =B4 | Y4: BRANCH: | Z4: =B4 | AD4: BRANCH: | AE4: =B4 | AI4: BRANCH: | AJ4: CASA DENTAL AMK PTE LTD | AN4: BRANCH: | AO4: =AE4 | AS4: BRANCH: | AT4: =AO4 | AX4: BRANCH: | AY4: =V4
A5: ALL PROVIDERS SETTLEMENT | E5: DR CHAN KC | I5: DR CHAN CHIEN CHI | M5: DR CELINE TEO | Q5: DR KALIE | U5: DR ROLAND FOO | Y5: DR JENNIFER HOANG | AD5: DR ESTHER HOH | AI5: DR ANDREW YIN | AN5: DR YVETTE CHOW | AS5: DR PETER KEITH | AX5: DR ROLAND FOO
C6: ADMIN CHARGES | G6: ADMIN CHARGES | J6: TOTALS | K6: ADMIN CHARGES | O6: ADMIN CHARGES | S6: ADMIN CHARGES | W6: ADMIN CHARGES | AA6: ADMIN CHARGES | AF6: ADMIN CHARGES | AK6: ADMIN CHARGES | AP6: ADMIN CHARGES | AU6: ADMIN CHARGES | AZ6: ADMIN CHARGES
A7: AIA | C7: =B7*0.05*1.09 | E7: AIA | G7: =F7*0.05*1.09 | I7: AIA | K7: =J7*0.05*1.09 | M7: AIA | O7: =N7*0.05*1.09 | Q7: AIA | S7: =R7*0.05*1.09 | U7: AIA | W7: =V7*0.05*1.09 | Y7: AIA | AA7: =Z7*0.05*1.09 | AD7: AIA | AF7: =AE7*0.05*1.09 | AI7: AIA | AK7: =AJ7*0.05*1.09 | AN7: AIA | AP7: =AO7*0.05*1.09 | AS7: AIA | AU7: =AT7*0.05*1.09 | AX7: AIA | AZ7: =AY7*0.05*1.09
A8: ALLIANCE | C8: =B8*0.05*1.09 | E8: ALLIANCE | G8: =F8*0.05*1.09 | I8: ALLIANCE | K8: =J8*0.05*1.09 | M8: ALLIANCE | O8: =N8*0.05*1.09 | U8: ALLIANCE | W8: =V8*0.05*1.09 | Y8: ALLIANCE | AA8: =Z8*0.05*1.09 | AD8: ALLIANCE | AF8: =AE8*0.05*1.09 | AN8: ALLIANCE | AP8: =AO8*0.05*1.09 | AS8: ALLIANCE | AU8: =AT8*0.05*1.09 | AX8: ALLIANCE | AZ8: =AY8*0.05*1.09
A9: AMEX | C9: =B9*0.0195 | E9: AMEX | G9: =F9*0.0195 | I9: AMEX | K9: =J9*0.0195 | M9: AMEX | O9: =N9*0.0195 | Q9: AMEX | S9: =R9*0.0195 | U9: AMEX | W9: =V9*0.0195 | Y9: AMEX | AA9: =Z9*0.0195 | AD9: AMEX | AF9: =AE9*0.0195 | AI9: AMEX | AK9: =AJ9*0.0195 | AN9: AMEX | AP9: =AO9*0.0195 | AS9: AMEX | AU9: =AT9*0.0195 | AX9: AMEX | AZ9: =AY9*0.0195
A10: BABYBONUS | C10: =B10*0.008 | E10: BABYBONUS | G10: =F10*0.008 | I10: BABYBONUS | K10: =J10*0.008 | M10: BABYBONUS | O10: =N10*0.008 | U10: BABYBONUS | W10: =V10*0.008 | Y10: BABYBONUS | AA10: =Z10*0.008 | AD10: BABYBONUS | AF10: =AE10*0.008 | AN10: BABYBONUS | AP10: =AO10*0.008 | AS10: BABYBONUS | AU10: =AT10*0.008 | AX10: BABYBONUS | AZ10: =AY10*0.008
A11: CASH | E11: CASH | I11: CASH | M11: CASH | Q11: ALLIANCE | S11: =R11*0.05*1.09 | U11: CASH | Y11: CASH | AD11: CASH | AI11: ALLIANCE | AK11: =AJ11*0.05*1.09 | AN11: CASH | AS11: CASH | AX11: CASH
A12: CASA VOUCHER | E12: CASA VOUCHER | I12: CASA VOUCHER | M12: CASA VOUCHER | Q12: CASH | U12: CASA VOUCHER | Y12: CASA VOUCHER | AD12: CASA VOUCHER | AI12: CASH | AN12: CASA VOUCHER | AS12: CASA VOUCHER | AX12: CASA VOUCHER
A13: CDC VOUCHER | E13: CDC VOUCHER | I13: CDC VOUCHER | M13: CDC VOUCHER | Q13: CASA VOUCHER | U13: CDC VOUCHER | Y13: CDC VOUCHER | AD13: CDC VOUCHER | AI13: CASA VOUCHER | AN13: CDC VOUCHER | AS13: CDC VOUCHER | AX13: CDC VOUCHER
A14: CHAS | E14: CHAS | I14: CHAS | M14: CHAS | U14: CHAS | Y14: CHAS | AD14: CHAS | AN14: CHAS | AS14: CHAS | AX14: CHAS
A15: CYNERGY | E15: CYNERGY | I15: CYNERGY | M15: CYNERGY | U15: CYNERGY | Y15: CYNERGY | AD15: CYNERGY | AN15: CYNERGY | AS15: CYNERGY | AX15: CYNERGY
A16: DA ADEPT HEALTH | C16: =B16*8% | E16: DA ADEPT HEALTH | G16: =F16*8% | I16: DA ADEPT HEALTH | K16: =J16*8% | M16: DA ADEPT HEALTH | O16: =N16*8% | U16: DA ADEPT HEALTH | W16: =V16*8% | Y16: DA ADEPT HEALTH | AA16: =Z16*8% | AD16: DA ADEPT HEALTH | AF16: =AE16*8% | AN16: DA ADEPT HEALTH | AP16: =AO16*8% | AS16: DA ADEPT HEALTH | AU16: =AT16*8% | AX16: DA ADEPT HEALTH | AZ16: =AY16*8%
A17: DEPOSIT | C17: =G17+K17+O17+O17+S17+W17+AA17+AF17+AP17+AU17+AZ17 | E17: DEPOSIT | I17: DEPOSIT | M17: DEPOSIT | Q17: DEPOSIT | S17: 0 | U17: DEPOSIT | Y17: DEPOSIT | AD17: DEPOSIT | AI17: DEPOSIT | AN17: DEPOSIT | AS17: DEPOSIT | AX17: DEPOSIT
A18: IHP | C18: =B18*0.051*1.09 | E18: IHP | G18: =F18*0.051*1.09 | I18: IHP | K18: =J18*0.051*1.09 | M18: IHP | O18: =N18*0.051*1.09 | U18: IHP | W18: =V18*0.051*1.09 | Y18: IHP | AA18: =Z18*0.051*1.09 | AD18: IHP | AF18: =AE18*0.051*1.09 | AN18: IHP | AP18: =AO18*0.051*1.09 | AS18: IHP | AU18: =AT18*0.051*1.09 | AX18: IHP | AZ18: =AY18*0.051*1.09
A19: JCB | C19: =B19*0.15*1.09 | E19: JCB | G19: =F19*0.15*1.09 | I19: JCB | K19: =J19*0.15*1.09 | M19: JCB | O19: =N19*0.15*1.09 | U19: JCB | W19: =V19*0.15*1.09 | Y19: JCB | AA19: =Z19*0.15*1.09 | AD19: JCB | AF19: =AE19*0.15*1.09 | AN19: JCB | AP19: =AO19*0.15*1.09 | AS19: JCB | AU19: =AT19*0.15*1.09 | AX19: JCB | AZ19: =AY19*0.15*1.09
A20: MASTER | C20: =B20*0.0225 | E20: MASTER | G20: =F20*0.021 | I20: MASTER | K20: =J20*0.0225 | M20: MASTER | O20: =N20*0.0225 | U20: MASTER | W20: =V20*0.0225 | Y20: MASTER | AA20: =Z20*0.0225 | AD20: MASTER | AF20: =AE20*0.0225 | AN20: MASTER | AP20: =AO20*0.0225 | AS20: MASTER | AU20: =AT20*0.0225 | AX20: MASTER | AZ20: =AY20*0.021
A21: MEDISAVE | E21: MEDISAVE | I21: MEDISAVE | M21: MEDISAVE | U21: MEDISAVE | Y21: MEDISAVE | AD21: MEDISAVE | AN21: MEDISAVE | AS21: MEDISAVE | AX21: MEDISAVE
A22: mednefits | C22: =B22*20% | E22: mednefits | G22: =F22*20% | I22: mednefits | K22: =J22*20% | M22: mednefits | O22: =N22*20% | U22: mednefits | W22: =V22*20% | Y22: mednefits | AA22: =Z22*20% | AD22: mednefits | AF22: =AE22*20% | AN22: mednefits | AP22: =AO22*20% | AS22: mednefits | AU22: =AT22*20% | AX22: mednefits | AZ22: =AY22*20%
A23: MHC | C23: =B23*0.15*1.09 | E23: MHC | G23: =F23*0.15*1.09 | I23: MHC | K23: =J23*0.15*1.09 | M23: MHC | O23: =N23*0.15*1.09 | U23: MHC | W23: =V23*0.15*1.09 | Y23: MHC | AA23: =Z23*0.15*1.09 | AD23: MHC | AF23: =AE23*0.15*1.09 | AN23: MHC | AP23: =AO23*0.15*1.09 | AS23: MHC | AU23: =AT23*0.15*1.09 | AX23: MHC | AZ23: =AY23*0.15*1.09
A24: NETS | C24: =B24*0.008 | E24: NETS | G24: =F24*0.008 | I24: NETS | K24: =J24*0.008 | M24: NETS | O24: =N24*0.008 | U24: NETS | W24: =V24*0.008 | Y24: NETS | AA24: =Z24*0.008 | AD24: NETS | AF24: =AE24*0.008 | AN24: NETS | AP24: =AO24*0.008 | AS24: NETS | AU24: =AT24*0.008 | AX24: NETS | AZ24: =AY24*0.008
A25: PARKWAY | C25: =B25*10% | E25: PARKWAY | G25: =F25*10% | I25: PARKWAY | K25: =J25*10% | M25: PARKWAY | O25: =N25*10% | U25: PARKWAY | W25: =V25*10% | Y25: PARKWAY | AA25: =Z25*10% | AD25: PARKWAY | AF25: =AE25*10% | AN25: PARKWAY | AP25: =AO25*10% | AS25: PARKWAY | AU25: =AT25*10% | AX25: PARKWAY | AZ25: =AY25*10%
A26: PAYNOW | E26: PAYNOW | I26: PAYNOW | M26: PAYNOW | U26: PAYNOW | Y26: PAYNOW | AD26: PAYNOW | AN26: PAYNOW | AS26: PAYNOW | AX26: PAYNOW
A27: RHI | E27: RHI | I27: RHI | M27: RHI | U27: RHI | Y27: RHI | AD27: RHI | AN27: RHI | AS27: RHI | AX27: RHI
A28: SAH | C28: =B28*8% | E28: SAH | G28: =F28*8% | I28: SAH | K28: =J28*8% | M28: SAH | O28: =N28*8% | U28: SAH | W28: =V28*8% | Y28: SAH | AA28: =Z28*8% | AD28: SAH | AF28: =AE28*8% | AN28: SAH | AP28: =AO28*8% | AS28: SAH | AU28: =AT28*8% | AX28: SAH | AZ28: =AY28*8%
A29: UNION PAY | C29: =B29*2.5% | E29: UNION PAY | G29: =F29*2.5% | I29: UNION PAY | K29: =J29*2.5% | M29: UNION PAY | O29: =N29*2.5% | U29: UNION PAY | W29: =V29*2.5% | Y29: UNION PAY | AA29: =Z29*2.5% | AD29: UNION PAY | AF29: =AE29*2.5% | AN29: UNION PAY | AP29: =AO29*2.5% | AS29: UNION PAY | AU29: =AT29*2.5% | AX29: UNION PAY | AZ29: =AY29*2.5%
A30: VISA | C30: =B30*0.0225 | E30: VISA | G30: =F30*0.021 | I30: VISA | K30: =J30*0.0225 | M30: VISA | O30: =N30*0.0225 | U30: VISA | W30: =V30*0.0225 | Y30: VISA | AA30: =Z30*0.0225 | AD30: VISA | AF30: =AE30*0.0225 | AN30: VISA | AP30: =AO30*0.0225 | AS30: VISA | AU30: =AT30*0.0225 | AX30: VISA | AZ30: =AY30*0.021
A31: TOTAL INCOME | B31: =SUM(B7:B30) | C31: =SUM(C7:C30) | E31: DR TOTAL INCOME | F31: =SUM(F7:F30) | G31: =SUM(G7:G30) | I31: DR TOTAL INCOME | J31: =SUM(J7:J30) | K31: =SUM(K7:K30) | M31: DR TOTAL INCOME | N31: =SUM(N7:N30) | O31: =SUM(O7:O30) | U31: DR TOTAL INCOME | V31: =SUM(V7:V30) | W31: =SUM(W7:W30) | Y31: DR TOTAL INCOME | Z31: =SUM(Z7:Z30) | AA31: =SUM(AA7:AA30) | AD31: DR TOTAL INCOME | AE31: =SUM(AE7:AE30) | AF31: =SUM(AF7:AF30) | AN31: DR TOTAL INCOME | AO31: =SUM(AO7:AO30) | AP31: =SUM(AP7:AP30) | AS31: DR TOTAL INCOME | AT31: =SUM(AT7:AT30) | AU31: =SUM(AU7:AU30) | AX31: DR TOTAL INCOME | AY31: =SUM(AY7:AY30) | AZ31: =SUM(AZ7:AZ30)
B33: EXPENSES | F33: DEDUCTIONS | H33: REMARKS | J33: DEDUCTIONS | L33: REMARKS | N33: DEDUCTIONS | P33: REMARKS | R33: DEDUCTIONS | T33: REMARKS | V33: DEDUCTIONS | X33: REMARKS | Z33: DEDUCTIONS | AB33: REMARKS | AE33: DEDUCTIONS | AG33: REMARKS | AJ33: DEDUCTIONS | AL33: REMARKS | AO33: DEDUCTIONS | AQ33: REMARKS | AT33: DEDUCTIONS | AV33: REMARKS | AY33: DEDUCTIONS | BA33: REMARKS
B34: ADMIN FEE | C34: =SUM(C7:C30) | F34: ADMIN CHARGES | G34: =G31 | J34: ADMIN CHARGES | K34: =K31 | N34: ADMIN CHARGES | O34: =O31 | R34: ADMIN CHARGES | S34: =#REF! | V34: ADMIN CHARGES | W34: =W31 | Z34: ADMIN CHARGES | AA34: =AA31 | AE34: ADMIN CHARGES | AF34: =AF31 | AJ34: ADMIN CHARGES | AK34: =#REF! | AO34: ADMIN CHARGES | AP34: =AP31 | AT34: ADMIN CHARGES | AU34: =AU31 | AY34: ADMIN CHARGES | AZ34: =AZ31
B35: GST | C35: =K35+O35+AA35+AF35+AM35+AP35+T35+W35+AU35+AZ35 | F35: GST | J35: GST | N35: GST | R35: GST | V35: GST | Z35: GST | AE35: GST | AJ35: GST | AO35: GST | AT35: GST | AY35: GST
B36: RENTAL | F36: ICC-5 | J36: ICC-5 | N36: ICC-5 | V36: ICC-5 | Z36: ICC-5 | AE36: ICC-5 | AO36: ICC-5 | AT36: ICC-5 | AY36: ICC-5
B37: LOAN INTEREST | F37: PRODUCTS | J37: PRODUCTS | N37: PRODUCTS | V37: PRODUCTS | Z37: PRODUCTS | AE37: PRODUCTS | AO37: PRODUCTS | AT37: PRODUCTS | AY37: PRODUCTS
B38: IRAS TAX | F38: ORTHO (B+B) | J38: ORTHO (B+B) | N38: ORTHO (B+B) | V38: ORTHO (B+B) | Z38: ORTHO (B+B) | AE38: ORTHO (B+B) | AO38: ORTHO (B+B) | AT38: ORTHO (B+B) | AY38: ORTHO (B+B)
B39: CK SECRETARIAL / ACCOUNTS SERVICES | F39: ABUTMENTS | J39: ABUTMENTS | N39: ABUTMENTS | V39: ABUTMENTS | Z39: ABUTMENTS | AE39: ABUTMENTS | AO39: ABUTMENTS | AT39: ABUTMENTS | AY39: ABUTMENTS
B40: TOWN COUNCIL | F40: IMPLANT | J40: IMPLANT | N40: IMPLANT | V40: IMPLANT | Z40: IMPLANT | AE40: IMPLANT | AO40: IMPLANT | AT40: IMPLANT | AY40: IMPLANT
B41: SERVICE & CONSERVANCY CHARGES | F41: SKY LAB | J41: SKY LAB | N41: SKY LAB | V41: SKY LAB | Z41: SKY LAB | AE41: SKY LAB | AO41: SKY LAB | AT41: SKY LAB | AY41: SKY LAB
B42: SP | F42: DIGICADCAM | J42: DIGICADCAM | N42: DIGICADCAM | V42: DIGICADCAM | Z42: DIGICADCAM | AE42: DIGICADCAM | AO42: DIGICADCAM | AT42: DIGICADCAM | AY42: DIGICADCAM
B43: SINGTEL | F43: OTHER LAB | J43: OTHER LAB | N43: OTHER LAB | V43: OTHER LAB | Z43: OTHER LAB | AE43: OTHER LAB | AO43: OTHER LAB | AT43: OTHER LAB | AY43: OTHER LAB
...

Sheet BEDOK SETTLEMENT CAL NEW
